Workbook

Sheet Apr 26_Supreme
A1: Sr. No. | B1: Particulars | C1: Value | D1: Units
A2: 1 | B2: Technical
A3: a | B3: Capacity | C3: 2600 | D3: MW
A4: b | B4: Specific Generation | C4: 1550 | D4: kWh/kWp
A6: 2 | B6: Commerical
A7: a | B7: EPC Rate | C7: 33000 | D7: ₹/kWp
A8: b | B8: EPC Cost | C8: =C7*C3 -> 85800000
A9: c | B9: Land Cost | C9: =C3*3*650000/1000 -> 5070000
A10: d | B10: Total Project Cost | C10: =(C7*C3)+C9 -> 90870000
A11: g | B11: O&M rate | C11: 650 | D11: /kWp/annum
A12: h | B12: O&M Cost | C12: =C11*C3 -> 1690000 | D12: /annum
A14: 2 | B14: Open Access Working
A15: 1 | B15: Solar Generation Capacity | C15: 4499.83 | D15: kWp
B16: Solar Generation Capacity | C16: 3300 | D16: kW
A17: 2 | B17: CUF | C17: =C4/8760 -> 0.17694064
A18: 3 | B18: Solar Supplied unit at Generation Bus Bar | C18: =G40 -> 237415
A19: 3.b | B19: Less: Wheeling Loss (7.50%) | C19: =C18*0.075 -> 17806.125
A20: 3.c | B20: Less: State Transmission Loss (3.28%) | C20: =(C18-C19)*3.28% -> 7203.1711
A21: 3.d | B21: Quantum at buyers periphery | C21: =C18-C19-C20 -> 212405.7
A22: 4.a | B22: Add: Wheeling Charge (0.74) | C22: =G40*0.81 -> 192306.15
A23: 4.b | B23: Add: State Transmission Charge (0.8771) | C23: 242163.3
A24: 4.c | B24: Add: Operating Charge | C24: =IF(C16<5000,16500,29830) -> 16500
A25: 5 | B25: Total Charges | C25: =SUM(C22:C24) -> 450969.45
A27: 4 | B27: Consumption Details
A28: a | B28: Month | C28: 46113
A29: b | B29: Contract Demand (kVA) | C29: 1800
A30: c | B30: Energy Charges (₹/kVAh) | C30: 8.44
A31: d | B31: Demand Charges (₹/kVA) | C31: 650
A32: e | B32: Wheeling Charges (₹/kVAh) | C32: 0.81
A33: f | B33: FAC (₹/kVAh) | C33: 0.5
A34: g | B34: Tax on Sales (₹/kVAh) | C34: 0.2894
A35: h | B35: Power Factor | C35: 1
A36: i | B36: Maximum Demand (kVA) | C36: 1488
A37: j | B37: Electricity Duty | C37: 0.075 | D37: 8.44 | E37: =7.17-C30 -> -1.27 | F37: =10.55-C30 -> 2.11 | K37: Reference for TOD calculation of Solar Generation
C38: Zone A | D38: Zone B | E38: Zone C | F38: Zone D | G38: Total | K38: Zone A | L38: Zone B | M38: Zone C | N38: Zone D | O38: Total
A39: k | B39: Consumption Before Solar | C39: =SUM(C40:C41) -> 166499 | D39: =SUM(D40:D41) -> 71263.75 | E39: =SUM(E40:E41) -> 215033.75 | F39: =SUM(F40:F41) -> 210750.5 | G39: =SUM(G40:G41) -> 663547 | I39: =C34*C35*G41 -> 123322.6 | J39: TOD Charges | K39: =K41+K40 -> 166499 | L39: =L41+L40 -> 71263.75 | M39: =M41+M40 -> 215033.75 | N39: =N41+N40 -> 210750.5 | O39: =SUM(K39:N39) -> 663547
A40: l | B40: Solar Units at consumption end | C40: =K40/C35 -> 0 | D40: =L40/C35 -> 11870.75 | E40: =M40/C35 -> 201802.75 | F40: =N40/C35 -> 23741.5 | G40: =SUM(C40:F40) -> 237415 | H40: 209644 | I40: TOD SOLAR Generation metre | K40: =P40*K43 -> 0 | L40: =P40*L43 -> 11870.75 | M40: =P40*M43 -> 201802.75 | N40: =P40*N43 -> 23741.5 | O40: =SUM(K40:N40) -> 237415 | P40: 237415
A41: m | B41: Billed Consumption after Solar | C41: =K41/C35 -> 166499 | D41: =L41/C35 -> 59393 | E41: =M41/C35 -> 13231 | F41: =N41/C35 -> 187009 | G41: =SUM(C41:F41) -> 426132 | K41: 166499 | L41: 59393 | M41: 13231 | N41: 187009 | O41: =SUM(K41:N41) -> 426132
A42: n | B42: TOD Rate | C42: 0 | D42: 0 | E42: -1.27 | F42: 2.11 | K42: 0 | L42: 0 | M42: -2.17 | N42: 2.17
B43: Load Factor | C43: =ROUND(G39*100/C29/24/DAY(EOMONTH(C28,0)),0) -> 51 | D43: =ROUND(G41*100/C29/24/DAY(EOMONTH(C28,0)),0) -> 33 | K43: 0 | L43: 0.05 | M43: 0.85 | N43: 0.1
...

Sheet Bill After Solar_Apr 26
A1: Sr. No. | B1: Particulars | C1: Before Solar | D1: After Solar - Captive
A2: 1 | B2: Consumption Details
A3: a | B3: Base month | C3: 46113 | D3: =C3 -> 46113
A4: b | B4: Source 1 - MSEDCL | C4: ='Apr 26_Supreme'!G39 -> 663547 | D4: ='Apr 26_Supreme'!G41 -> 426132
A5: c | B5: Source 2 - Solar Power Plant | C5: 0 | D5: ='Apr 26_Supreme'!G40 -> 237415
A6: d | B6: Total Consumption | C6: =C4+C5 -> 663547 | D6: =D4+D5 -> 663547
A8: 2 | B8: Computation of Electricity Bill based on consumption in Apr-26
A9: A | B9: Bill for MSEDCL Consumption
A10: i | B10: Demand Charges | C10: ='Apr 26_Supreme'!$C$45*'Apr 26_Supreme'!$C$31 -> 967200 | D10: ='Apr 26_Supreme'!$C$45*'Apr 26_Supreme'!$C$31 -> 967200
A11: ii | B11: Wheeling Charges | C11: ='Apr 26_Supreme'!$G$39*'Apr 26_Supreme'!$C$32 -> 537473.07 | D11: ='Apr 26_Supreme'!$G$41*'Apr 26_Supreme'!$C$32 -> 345166.92
A12: iii | B12: Energy Charges | C12: ='Apr 26_Supreme'!$G$39*'Apr 26_Supreme'!$C$30 -> 5600336.7 | D12: ='Apr 26_Supreme'!$G$41*'Apr 26_Supreme'!$C$30 -> 3596554.1
A13: iv | B13: TOD Tariff Energy Charges | C13: {=SUMPRODUCT('Apr 26_Supreme'!$C$39:$F$39,'Apr 26_Supreme'!$C$42:$F$42)} -> 171590.69 | D13: {=SUMPRODUCT('Apr 26_Supreme'!$C$41:$F$41,'Apr 26_Supreme'!$C$42:$F$42)} -> 377785.62
A14: v | B14: FAC | C14: ='Apr 26_Supreme'!$G$39*'Apr 26_Supreme'!$C$33 -> 331773.5 | D14: ='Apr 26_Supreme'!$G$41*'Apr 26_Supreme'!$C$33 -> 213066
A15: vi | B15: Electricity Duty | C15: =(SUM(C10:C14)+C20)*'Apr 26_Supreme'!$C$37 -> 570628.05 | D15: =(SUM(D10:D14)+D20)*'Apr 26_Supreme'!$C$37 -> 412482.95
A16: vii | B16: Bulk Consumption Rebate | C16: {=-SUMPRODUCT('Apr 26_Supreme'!C47:C49,'Apr 26_Supreme'!$C$51:$C$53)} -> -39448.29 | D16: {=-SUMPRODUCT('Apr 26_Supreme'!D47:D49,'Apr 26_Supreme'!$C$51:$C$53)} -> -22829.24
A17: viii | B17: Tax on Sale | C17: ='Apr 26_Supreme'!$C$34*'Apr 26_Supreme'!$C$35*'Apr 26_Supreme'!$G$39 -> 192030.5 | D17: ='Apr 26_Supreme'!$C$34*'Apr 26_Supreme'!$C$35*'Apr 26_Supreme'!$G$41 -> 123322.6
A18: ix | B18: Load Factor Incentive | C18: 0 | D18: 0
A19: x | B19: Incremental Consumption Rebate | C19: =IF(((C4-'Apr 26_Supreme'!C55)*-0.75*'Apr 26_Supreme'!C35)>0,0,((C4-'Apr 26_Supreme'!C55)*-0.75*'Apr 26_Supreme'!C35)) -> -74373 | D19: =IF(((D4-'Apr 26_Supreme'!C55)*-0.75*'Apr 26_Supreme'!C35)>0,0,((D4-'Apr 26_Supreme'!C55)*-0.75*'Apr 26_Supreme'!C35)) -> 0
A20: xi | B20: Charges for Excess Demand | C20: =D20 -> 0 | D20: =IF('Apr 26_Supreme'!D36>'Apr 26_Supreme'!C29,(('Apr 26_Supreme'!D36-'Apr 26_Supreme'!C29)*1.5*'Apr 26_Supreme'!D31),0) -> 0
A21: xii | B21: Tax Collection at Source | C21: 0 | D21: 0
A22: xiii | B22: Debit Bill adjustment | C22: 0 | D22: 609816.75
A23: xiv | B23: Total Bill for MSEDCL Consumption | C23: =SUM(C10:C22) -> 8257211.2 | D23: =SUM(D10:D22) -> 6622565.7
A24: B | B24: Bill for Open Access
B25: Tax on Sale | D25: ='Apr 26_Supreme'!C34*'Apr 26_Supreme'!C35*'Apr 26_Supreme'!G40 -> 68707.901
A26: i | B26: Wheeling Charges | C26: 0 | D26: ='Apr 26_Supreme'!C22 -> 192306.15
A27: ii | B27: Transmission Charges | C27: 0 | D27: ='Apr 26_Supreme'!C23 -> 242163.3
A28: iii | B28: Operating Charges | C28: 0 | D28: ='Apr 26_Supreme'!C24 -> 16500
A29: iv | B29: Total Bill for Open Access | C29: =SUM(C26:C28) -> 0 | D29: =SUM(D25:D28) -> 519677.35
A30: C | B30: Total MSEDCL Bill | C30: =C29+C23 -> 8257211.2 | D30: =D29+D23 -> 7142243
A31: D | B31: O&M Cost per month | C31: 0
A32: D | B32: Total Cost of power | C32: =C31+C30 -> 8257211.2 | D32: =D31+D30 -> 7142243
A33: F | B33: Net Savings | D33: =$C$32-D32 -> 1114968.2
A34: G | B34: Simple Payback ( Capex Cost / Monthly Savings) | D34: =ROUNDUP(('Apr 26_Supreme'!C10/D33),0) -> 82
A35: D | B35: Average Cost of Power | C35: =C32/C6 -> 12.444049 | D35: =D32/D6 -> 10.763733
A36: E | B36: Total Savings | D36: =C30-D30 -> 1114968.2
A37: F | B37: % Savings | D37: =D36/C32 -> 0.13502963
